Workbook

Sheet Summary
A1: Approach Delay
E2: Before After Delay Calculations
A3: May 5th | F3: Average Approach Delay | G3: NBT Ph2 | H3: SBT Ph6
A4: Average Approach Delay | B4: 19.642552 | C4: Sec/Veh | E4: June 23rd and May 5th | F4: =B19-B4 -> 0.26869792 | G4: =B20-B5 -> -0.85729167 | H4: =B21-B6 -> 1.3946875
A5: NBT Ph2 | B5: 16.134583 | C5: Sec/Veh | E5: June 23rd and May 6th | F5: =B19-B9 -> -0.73234375 | G5: =B20-B5 -> -0.85729167 | H5: =B21-B11 -> 0.41072917
A6: SBT Ph6 | B6: 23.150521 | C6: Sec/Veh | E6: June 23rd and May 18th | F6: =B19-B14 -> 0.51177083 | G6: =B20-B15 -> -1.1726042 | H6: =B21-B16 -> 2.1961458
E7: July 14th vs May 5th | F7: =B24-B4 -> 0.0215625 | G7: =B25-B5 -> -1.4730208 | H7: =B26-B6 -> 1.5161458
A8: May 6th | E8: July 14th vs May 6th | F8: =B24-B9 -> -0.97947917 | G8: =B25-B10 -> -2.4911458 | H8: =B26-B11 -> 0.5321875
A9: Average Approach Delay | B9: 20.643594 | C9: Sec/Veh | E9: July 14th vs May 18th | F9: =B24-B14 -> 0.26463542 | G9: =B25-B15 -> -1.7883333 | H9: =B26-B16 -> 2.3176042
A10: NBT Ph2 | B10: 17.152708 | C10: Sec/Veh | E10: July 15th and May 5th | F10: =B29-B4 -> 0.55166667 | G10: =B30-B5 -> -0.36645833 | H10: =B31-B6 -> 1.4697917
A11: SBT Ph6 | B11: 24.134479 | C11: Sec/Veh | E11: July 15th and May 6th | F11: =B29-B9 -> -0.449375 | G11: =B30-B10 -> -1.3845833 | H11: =B31-B11 -> 0.48583333
E12: July 15th and May 18th | F12: =B29-B14 -> 0.79473958 | G12: =B30-B15 -> -0.68177083 | H12: =B31-B16 -> 2.27125
A13: May 18th | E13: Overall Average | F13: =AVERAGE(F4:F12) -> 0.027986111 | G13: =AVERAGE(G4:G12) -> -1.2302778 | H13: =AVERAGE(H4:H12) -> 1.399375
A14: Average Approach Delay | B14: 19.399479 | C14: Sec/Veh
A15: NBT Ph2 | B15: 16.449896 | C15: Sec/Veh | E15: No delay found after LPI implementation
A16: SBT Ph6 | B16: 22.349063 | C16: Sec/Veh
E17: Absolute Value Random Fluctuations Between Days
A18: June 23rd | F18: Average Approach Delay | G18: NBT Ph2 | H18: SBT Ph6
A19: Average Approach Delay | B19: 19.91125 | C19: Sec/Veh | E19: May 18th and May 5th | F19: =ABS(B14-B4) -> 0.24307292 | G19: =ABS(B15-B5) -> 0.3153125 | H19: =ABS(B16-B6) -> 0.80145833
A20: NBT Ph2 | B20: 15.277292 | C20: Sec/Veh | E20: May 18th and May 6th | F20: =ABS(B14-B9) -> 1.2441146 | G20: =ABS(B15-B10) -> 0.7028125 | H20: =ABS(B16-B11) -> 1.7854167
A21: SBT Ph6 | B21: 24.545208 | C21: Sec/Veh | E21: May 6th and May 5th | F21: =ABS(B9-B4) -> 1.0010417 | G21: =ABS(B10-B5) -> 1.018125 | H21: =ABS(B11-B6) -> 0.98395833
E22: July 15th and June 23 | F22: =ABS(B29-B19) -> 0.28296875 | G22: =ABS(B30-B20) -> 0.49083333 | H22: =ABS(B31-B21) -> 0.075104167
A23: July 14th | E23: July 15th and July 14th | F23: =ABS(B29-B24) -> 0.53010417 | G23: =ABS(B30-B25) -> 1.1065625 | H23: =ABS(B31-B26) -> 0.046354167
A24: Average Approach Delay | B24: 19.664115 | C24: Sec/Veh | E24: July 14th and June 23rd | F24: =ABS(B24-B19) -> 0.24713542 | G24: =ABS(B25-B20) -> 0.61572917 | H24: =ABS(B26-B21) -> 0.12145833
A25: NBT Ph2 | B25: 14.661562 | C25: Sec/Veh | E25: Overall Average | F25: =AVERAGE(F19:F24) -> 0.59140625 | G25: =AVERAGE(G19:G24) -> 0.70822917 | H25: =AVERAGE(H19:H24) -> 0.635625
A26: SBT Ph6 | B26: 24.666667 | C26: Sec/Veh
E27: Random fluctuation of 0.6 seconds
A28: July 15th
A29: Average Approach Delay | B29: 20.194219 | C29: Sec/Veh | E29: LPI does not appear to have any impact on delay
A30: NBT Ph2 | B30: 15.768125 | C30: Sec/Veh
A31: SBT Ph6 | B31: 24.620313 | C31: Sec/Veh
A33: Arrival on Red
E34: Before After Arrival on Red Calculations (%)
A35: May 5th | F35: Average % Arrivals on Red | G35: NBT Ph2 | H35: SBT Ph6
A36: % Arrivals on Red | B36: 51.802031 | C36: % | E36: June 23rd and May 5th | F36: =B51-B36 -> 0.39609375 | G36: =B52-B37 -> -0.1790625 | H36: =B53-B38 -> 0.97125
A37: NBT Ph2 | B37: 46.609375 | C37: % | E37: June 23rd and May 6th | F37: =B51-B41 -> -2.3088542 | G37: =B52-B37 -> -0.1790625 | H37: =B53-B43 -> -1.0155208
A38: SBT Ph6 | B38: 56.994687 | C38: % | E38: June 23rd and May 18th | F38: =B51-B46 -> 1.7361979 | G38: =B52-B47 -> 0.35447917 | H38: =B53-B48 -> 3.1179167
E39: July 14th vs May 5th | F39: =B56-B36 -> -0.084427083 | G39: =B57-B37 -> -1.588125 | H39: =B58-B38 -> 1.4192708
A40: May 6th | E40: July 14th vs May 6th | F40: =B56-B41 -> -2.789375 | G40: =B57-B42 -> -5.01125 | H40: =B58-B43 -> -0.5675
A41: % Arrivals on Red | B41: 54.506979 | C41: % | E41: July 14th vs May 18th | F41: =B56-B46 -> 1.2556771 | G41: =B57-B47 -> -1.0545833 | H41: =B58-B48 -> 3.5659375
...

Sheet Normalized Delay
A1: Approach Delay
A2: Normalization Factors
B3: Total Traffic Volumes | C3: NBT Ph2 | D3: SBT Ph6 | E3: Total Weight Factor | F3: NBT Ph2 Weight Factor | G3: SBT Weight Factor
A4: May 5th | B4: {=TRANSPOSE('Traffic Volumes'!B8:B10)} -> 76294 | C4: 32915 | D4: 43379 | E4: =B$10/B4 -> 0.84726628 | F4: =C$10/C4 -> 0.85633197 | G4: =D$10/D4 -> 0.84038744
A5: May 6th | B5: {=TRANSPOSE('Traffic Volumes'!H8:H10)} -> 83144 | C5: 35669 | D5: 47475 | E5: =B$10/B5 -> 0.77746239 | F5: =C$10/C5 -> 0.79021466 | G5: =D$10/D5 -> 0.76788134
A6: May 18th | B6: {=TRANSPOSE('Traffic Volumes'!N8:N10)} -> 86218 | C6: 36652 | D6: 49566 | E6: =B$10/B6 -> 0.7497429 | F6: =C$10/C6 -> 0.76902124 | G6: =D$10/D6 -> 0.73548736
A7: June 23rd | B7: {=TRANSPOSE('Traffic Volumes'!T8:T10)} -> 54952 | C7: 24357 | D7: 30595 | E7: =B$10/B7 -> 1.1763236 | F7: =C$10/C7 -> 1.1572101 | G7: =D$10/D7 -> 1.19154
A8: July 14th | B8: {=TRANSPOSE('Traffic Volumes'!Z8:Z10)} -> 43881 | C8: 19672 | D8: 24209 | E8: =B$10/B8 -> 1.4731053 | F8: =C$10/C8 -> 1.4328064 | G8: =D$10/D8 -> 1.5058518
A9: July 15th | B9: {=TRANSPOSE('Traffic Volumes'!AF8:AF10)} -> 43359 | C9: 19852 | D9: 23507 | E9: =B$10/B9 -> 1.49084 | F9: =C$10/C9 -> 1.419815 | G9: =D$10/D9 -> 1.5508217
A10: Average | B10: =AVERAGE(B4:B9) -> 64641.333 | C10: =AVERAGE(C4:C9) -> 28186.167 | D10: =AVERAGE(D4:D9) -> 36455.167 | E10: =B$10/B10 -> 1 | F10: =C$10/C10 -> 1 | G10: =D$10/D10 -> 1
F12: Before After Normalized Delay Calculations (Sec/Veh)
A13: May 5th | B13: Delay | D13: Normalized Delay | G13: Average Approach Delay | H13: NBT Ph2 | I13: SBT Ph6
A14: Average Approach Delay | B14: 19.642552 | C14: Sec/Veh | D14: =B14*E4 -> 16.642472 | E14: Sec/Veh | F14: June 23rd and May 5th | G14: =D29-D14 -> 6.7796009 | H14: =D30-D15 -> 3.8624769 | I14: =D31-D16 -> 9.7911909
A15: NBT Ph2 | B15: 16.134583 | C15: Sec/Veh | D15: =B15*F4 -> 13.816559 | E15: Sec/Veh | F15: June 23rd and May 6th | G15: =D29-D19 -> 7.372455 | H15: =D30-D15 -> 3.8624769 | I15: =D31-D21 -> 10.714182
A16: SBT Ph6 | B16: 23.150521 | C16: Sec/Veh | D16: =B16*G4 -> 19.455407 | E16: Sec/Veh | F16: June 23rd and May 18th | G16: =D29-D24 -> 8.8774511 | H16: =D30-D25 -> 5.028717 | I16: =D31-D26 -> 12.809145
F17: July 14th vs May 5th | G17: =D34-D14 -> 12.324839 | H17: =D35-D15 -> 7.1906205 | I17: =D36-D16 -> 17.688938
A18: May 6th | F18: July 14th vs May 6th | G18: =D34-D19 -> 12.917693 | H18: =D35-D20 -> 7.4528584 | I18: =D36-D21 -> 18.611929
A19: Average Approach Delay | B19: 20.643594 | C19: Sec/Veh | D19: =B19*E5 -> 16.049618 | E19: Sec/Veh | F19: July 14th vs May 18th | G19: =D34-D24 -> 14.422689 | H19: =D35-D25 -> 8.3568606 | I19: =D36-D26 -> 20.706892
A20: NBT Ph2 | B20: 17.152708 | C20: Sec/Veh | D20: =B20*F5 -> 13.554322 | E20: Sec/Veh | F20: July 15th and May 5th | G20: =D39-D14 -> 13.463878 | H20: =D40-D15 -> 8.5712604 | I20: =D41-D16 -> 18.726309
A21: SBT Ph6 | B21: 24.134479 | C21: Sec/Veh | D21: =B21*G5 -> 18.532416 | E21: Sec/Veh | F21: July 15th and May 6th | G21: =D39-D19 -> 14.056732 | H21: =D40-D20 -> 8.8334983 | I21: =D41-D21 -> 19.6493
F22: July 15th and May 18th | G22: =D39-D24 -> 15.561728 | H22: =D40-D25 -> 9.7375005 | I22: =D41-D26 -> 21.744263
A23: May 18th | F23: Overall Average | G23: =AVERAGE(G14:G22) -> 11.753007 | H23: =AVERAGE(H14:H22) -> 6.9884744 | I23: =AVERAGE(I14:I22) -> 16.715794
A24: Average Approach Delay | B24: 19.399479 | C24: Sec/Veh | D24: =B24*E6 -> 14.544622 | E24: Sec/Veh
A25: NBT Ph2 | B25: 16.449896 | C25: Sec/Veh | D25: =B25*F6 -> 12.650319 | E25: Sec/Veh
A26: SBT Ph6 | B26: 22.349063 | C26: Sec/Veh | D26: =B26*G6 -> 16.437453 | E26: Sec/Veh
F27: Normalized Absolute Value Random Fluctuations Between Days (Sec/Veh)
A28: June 23rd | G28: Average Approach Delay | H28: NBT Ph2 | I28: SBT Ph6
A29: Average Approach Delay | B29: 19.91125 | C29: Sec/Veh | D29: =B29*E7 -> 23.422073 | E29: Sec/Veh | F29: May 18th and May 5th | G29: =ABS(D24-D14) -> 2.0978502 | H29: =ABS(D25-D15) -> 1.1662401 | I29: =ABS(D26-D16) -> 3.0179538
A30: NBT Ph2 | B30: 15.277292 | C30: Sec/Veh | D30: =B30*F7 -> 17.679036 | E30: Sec/Veh | F30: May 18th and May 6th | G30: =ABS(D24-D19) -> 1.5049961 | H30: =ABS(D25-D20) -> 0.90400219 | I30: =ABS(D26-D21) -> 2.0949632
A31: SBT Ph6 | B31: 24.545208 | C31: Sec/Veh | D31: =B31*G7 -> 29.246598 | E31: Sec/Veh | F31: May 6th and May 5th | G31: =ABS(D19-D14) -> 0.59285414 | H31: =ABS(D20-D15) -> 0.26223791 | I31: =ABS(D21-D16) -> 0.92299066
F32: July 15th and June 23 | G32: =ABS(D39-D29) -> 6.684277 | H32: =ABS(D40-D30) -> 4.7087834 | I32: =ABS(D41-D31) -> 8.9351181
A33: July 14th | F33: July 15th and July 14th | G33: =ABS(D39-D34) -> 1.1390386 | H33: =ABS(D40-D35) -> 1.3806399 | I33: =ABS(D41-D36) -> 1.037371
A34: Average Approach Delay | B34: 19.664115 | C34: Sec/Veh | D34: =B34*E8 -> 28.967311 | E34: Sec/Veh | F34: July 14th and June 23rd | G34: =ABS(D34-D29) -> 5.5452384 | H34: =ABS(D35-D30) -> 3.3281436 | I34: =ABS(D36-D31) -> 7.897747
A35: NBT Ph2 | B35: 14.661562 | C35: Sec/Veh | D35: =B35*F8 -> 21.00718 | E35: Sec/Veh | F35: Overall Average | G35: =AVERAGE(G29:G34) -> 2.9273757 | H35: =AVERAGE(H29:H34) -> 1.9583412 | I35: =AVERAGE(I29:I34) -> 3.9843573
A36: SBT Ph6 | B36: 24.666667 | C36: Sec/Veh | D36: =B36*G8 -> 37.144345 | E36: Sec/Veh
A38: July 15th
A39: Average Approach Delay | B39: 20.194219 | C39: Sec/Veh | D39: =B39*E9 -> 30.10635 | E39: Sec/Veh
A40: NBT Ph2 | B40: 15.768125 | C40: Sec/Veh | D40: =B40*F9 -> 22.38782 | E40: Sec/Veh
A41: SBT Ph6 | B41: 24.620313 | C41: Sec/Veh | D41: =B41*G9 -> 38.181716 | E41: Sec/Veh
A43: Arrival on Red
...

Sheet Traffic Volumes
A1: Before Data Day 1 | G1: Before Data Day 2 | M1: Before Data Day 3 | S1: After Data Day 1 | Y1: After Data Day 2 | AE1: After Data Day 3
A2: Performance Measures - ATSPM | G2: Performance Measures - ATSPM | M2: Performance Measures - ATSPM | S2: Performance Measures - ATSPM | Y2: Performance Measures - ATSPM | AE2: Performance Measures - ATSPM
A3: Traffic Volumes | G3: Traffic Volumes | M3: Traffic Volumes | S3: Traffic Volumes | Y3: Traffic Volumes | AE3: Traffic Volumes
A4: 6311 - State Street @ Center Street | G4: 6311 - State Street @ Center Street | M4: 6311 - State Street @ Center Street | S4: 6311 - State Street @ Center Street | Y4: 6311 - State Street @ Center Street | AE4: 6311 - State Street @ Center Street
A5: May 5 2026 at 00:00:00 - May 6 2026 at 00:00:00 | G5: May 6 2026 at 00:00:00 - May 7 2026 at 00:00:00 | M5: May 18 2026 at 00:00:00 - May 19 2026 at 00:00:00 | S5: June 23 2026 at 00:00:00 - June 24 2026 at 00:00:00 | Y5: July 14 2026 at 00:00:00 - July 15 2026 at 00:00:00 | AE5: July 15 2026 at 00:00:00 - July 16 2026 at 00:00:00
A7: Traffic Volumes Summary | G7: Traffic Volumes Summary | M7: Traffic Volumes Summary | S7: Traffic Volumes Summary | Y7: Traffic Volumes Summary | AE7: Traffic Volumes Summary
A8: Total Traffic Volumes | B8: =SUM(B14:B111,E14:E111)/4 -> 76294 | C8: Veh/Day | G8: Total Traffic Volumes | H8: =SUM(H14:H111,K14:K111)/4 -> 83144 | I8: Veh/Day | M8: Total Traffic Volumes | N8: =SUM(N14:N111,Q14:Q111)/4 -> 86218 | O8: Veh/Day | S8: Total Traffic Volumes | T8: =SUM(T14:T111,W14:W111)/4 -> 54952 | U8: Veh/Day | Y8: Total Traffic Volumes | Z8: =SUM(Z14:Z111,AC14:AC111)/4 -> 43881 | AA8: Veh/Day | AE8: Total Traffic Volumes | AF8: =SUM(AF14:AF111,AI14:AI111)/4 -> 43359 | AG8: Veh/Day
A9: NBT Ph2 | B9: =SUM(B14:B111)/4 -> 32915 | C9: Veh/Day | G9: NBT Ph2 | H9: =SUM(H14:H111)/4 -> 35669 | I9: Veh/Day | M9: NBT Ph2 | N9: =SUM(N14:N111)/4 -> 36652 | O9: Veh/Day | S9: NBT Ph2 | T9: =SUM(T14:T111)/4 -> 24357 | U9: Veh/Day | Y9: NBT Ph2 | Z9: =SUM(Z14:Z111)/4 -> 19672 | AA9: Veh/Day | AE9: NBT Ph2 | AF9: =SUM(AF14:AF111)/4 -> 19852 | AG9: Veh/Day
A10: SBT Ph6 | B10: =SUM(E14:E111)/4 -> 43379 | C10: Veh/Day | G10: SBT Ph6 | H10: =SUM(K14:K111)/4 -> 47475 | I10: Veh/Day | M10: SBT Ph6 | N10: =SUM(Q14:Q111)/4 -> 49566 | O10: Veh/Day | S10: SBT Ph6 | T10: =SUM(W14:W111)/4 -> 30595 | U10: Veh/Day | Y10: SBT Ph6 | Z10: =SUM(AC14:AC111)/4 -> 24209 | AA10: Veh/Day | AE10: SBT Ph6 | AF10: =SUM(AI14:AI111)/4 -> 23507 | AG10: Veh/Day
A12: NBT Ph2 | D12: SBT Ph6 | G12: NBT Ph2 | J12: SBT Ph6 | M12: NBT Ph2 | P12: SBT Ph6 | S12: NBT Ph2 | V12: SBT Ph6 | Y12: NBT Ph2 | AB12: SBT Ph6 | AE12: NBT Ph2 | AH12: SBT Ph6
A13: Total Vehicles | D13: Total Vehicles | G13: Total Vehicles | J13: Total Vehicles | M13: Total Vehicles | P13: Total Vehicles | S13: Total Vehicles | V13: Total Vehicles | Y13: Total Vehicles | AB13: Total Vehicles | AE13: Total Vehicles | AH13: Total Vehicles
A14: 1777960800000 | B14: 408 | D14: 1777960800000 | E14: 1392 | G14: 1778047200000 | H14: 1056 | J14: 1778047200000 | K14: 1420 | M14: 1779084000000 | N14: 876 | P14: 1779084000000 | Q14: 828 | S14: 1782194400000 | T14: 568 | V14: 1782194400000 | W14: 1152 | Y14: 1784008800000 | Z14: 368 | AB14: 1784008800000 | AC14: 612 | AE14: 1784095200000 | AF14: 280 | AH14: 1784095200000 | AI14: 424
A15: 1777961700000 | B15: 212 | D15: 1777961700000 | E15: 1276 | G15: 1778048100000 | H15: 868 | J15: 1778048100000 | K15: 1320 | M15: 1779084900000 | N15: 1088 | P15: 1779084900000 | Q15: 800 | S15: 1782195300000 | T15: 436 | V15: 1782195300000 | W15: 808 | Y15: 1784009700000 | Z15: 312 | AB15: 1784009700000 | AC15: 496 | AE15: 1784096100000 | AF15: 288 | AH15: 1784096100000 | AI15: 456
A16: 1777962600000 | B16: 284 | D16: 1777962600000 | E16: 1300 | G16: 1778049000000 | H16: 1004 | J16: 1778049000000 | K16: 1380 | M16: 1779085800000 | N16: 1020 | P16: 1779085800000 | Q16: 1140 | S16: 1782196200000 | T16: 536 | V16: 1782196200000 | W16: 788 | Y16: 1784010600000 | Z16: 284 | AB16: 1784010600000 | AC16: 584 | AE16: 1784097000000 | AF16: 168 | AH16: 1784097000000 | AI16: 484
A17: 1777963500000 | B17: 656 | D17: 1777963500000 | E17: 1240 | G17: 1778049900000 | H17: 856 | J17: 1778049900000 | K17: 1124 | M17: 1779086700000 | N17: 1092 | P17: 1779086700000 | Q17: 1104 | S17: 1782197100000 | T17: 428 | V17: 1782197100000 | W17: 768 | Y17: 1784011500000 | Z17: 248 | AB17: 1784011500000 | AC17: 524 | AE17: 1784097900000 | AF17: 220 | AH17: 1784097900000 | AI17: 444
A18: 1777964400000 | B18: 852 | D18: 1777964400000 | E18: 1292 | G18: 1778050800000 | H18: 932 | J18: 1778050800000 | K18: 1276 | M18: 1779087600000 | N18: 1288 | P18: 1779087600000 | Q18: 1824 | S18: 1782198000000 | T18: 312 | V18: 1782198000000 | W18: 776 | Y18: 1784012400000 | Z18: 256 | AB18: 1784012400000 | AC18: 540 | AE18: 1784098800000 | AF18: 136 | AH18: 1784098800000 | AI18: 564
A19: 1777965300000 | B19: 620 | D19: 1777965300000 | E19: 1364 | G19: 1778051700000 | H19: 756 | J19: 1778051700000 | K19: 3084 | M19: 1779088500000 | N19: 1068 | P19: 1779088500000 | Q19: 2992 | S19: 1782198900000 | T19: 376 | V19: 1782198900000 | W19: 820 | Y19: 1784013300000 | Z19: 208 | AB19: 1784013300000 | AC19: 560 | AE19: 1784099700000 | AF19: 176 | AH19: 1784099700000 | AI19: 464
A20: 1777966200000 | B20: 556 | D20: 1777966200000 | E20: 1252 | G20: 1778052600000 | H20: 1104 | J20: 1778052600000 | K20: 3444 | M20: 1779089400000 | N20: 988 | P20: 1779089400000 | Q20: 2540 | S20: 1782199800000 | T20: 356 | V20: 1782199800000 | W20: 684 | Y20: 1784014200000 | Z20: 172 | AB20: 1784014200000 | AC20: 460 | AE20: 1784100600000 | AF20: 192 | AH20: 1784100600000 | AI20: 372
A21: 1777967100000 | B21: 652 | D21: 1777967100000 | E21: 1192 | G21: 1778053500000 | H21: 936 | J21: 1778053500000 | K21: 3316 | M21: 1779090300000 | N21: 972 | P21: 1779090300000 | Q21: 2880 | S21: 1782200700000 | T21: 376 | V21: 1782200700000 | W21: 872 | Y21: 1784015100000 | Z21: 132 | AB21: 1784015100000 | AC21: 348 | AE21: 1784101500000 | AF21: 108 | AH21: 1784101500000 | AI21: 520
A22: 1777968000000 | B22: 616 | D22: 1777968000000 | E22: 1192 | G22: 1778054400000 | H22: 868 | J22: 1778054400000 | K22: 2980 | M22: 1779091200000 | N22: 952 | P22: 1779091200000 | Q22: 2760 | S22: 1782201600000 | T22: 500 | V22: 1782201600000 | W22: 936 | Y22: 1784016000000 | Z22: 100 | AB22: 1784016000000 | AC22: 508 | AE22: 1784102400000 | AF22: 116 | AH22: 1784102400000 | AI22: 476
A23: 1777968900000 | B23: 460 | D23: 1777968900000 | E23: 1068 | G23: 1778055300000 | H23: 632 | J23: 1778055300000 | K23: 2440 | M23: 1779092100000 | N23: 932 | P23: 1779092100000 | Q23: 2176 | S23: 1782202500000 | T23: 540 | V23: 1782202500000 | W23: 900 | Y23: 1784016900000 | Z23: 52 | AB23: 1784016900000 | AC23: 716 | AE23: 1784103300000 | AF23: 224 | AH23: 1784103300000 | AI23: 516
A24: 1777969800000 | B24: 612 | D24: 1777969800000 | E24: 1044 | G24: 1778056200000 | H24: 1024 | J24: 1778056200000 | K24: 2304 | M24: 1779093000000 | N24: 928 | P24: 1779093000000 | Q24: 2284 | S24: 1782203400000 | T24: 508 | V24: 1782203400000 | W24: 980 | Y24: 1784017800000 | Z24: 124 | AB24: 1784017800000 | AC24: 528 | AE24: 1784104200000 | AF24: 244 | AH24: 1784104200000 | AI24: 532
A25: 1777970700000 | B25: 388 | D25: 1777970700000 | E25: 812 | G25: 1778057100000 | H25: 776 | J25: 1778057100000 | K25: 2384 | M25: 1779093900000 | N25: 876 | P25: 1779093900000 | Q25: 2072 | S25: 1782204300000 | T25: 556 | V25: 1782204300000 | W25: 1016 | Y25: 1784018700000 | Z25: 180 | AB25: 1784018700000 | AC25: 616 | AE25: 1784105100000 | AF25: 44 | AH25: 1784105100000 | AI25: 444
... A109: 1778046300000 | B109: 1244 | D109: 1778046300000 | E109: 1144 | G109: 1778132700000 | H109: 1328 | J109: 1778132700000 | K109: 1608 | M109: 1779169500000 | N109: 1096 | P109: 1779169500000 | Q109: 1660 | S109: 1782279900000 | T109: 532 | V109: 1782279900000 | W109: 1108 | Y109: 1784094300000 | Z109: 424 | AB109: 1784094300000 | AC109: 668 | AE109: 1784180700000 | AF109: 232 | AH109: 1784180700000 | AI109: 456

Sheet Approach Delay
A1: Before Data Day 1 | G1: Before Data Day 2 | M1: Before Data Day 3 | S1: After Data Day 1 | Y1: After Data Day 2 | AE1: After Data Day 3
A2: Performance Measures - ATSPM | G2: Performance Measures - ATSPM | M2: Performance Measures - ATSPM | S2: Performance Measures - ATSPM | Y2: Performance Measures - ATSPM | AE2: Performance Measures - ATSPM
A3: Approach Delay | G3: Approach Delay | M3: Approach Delay | S3: Approach Delay | Y3: Approach Delay | AE3: Approach Delay
A4: 6311 - State Street @ Center Street | G4: 6311 - State Street @ Center Street | M4: 6311 - State Street @ Center Street | S4: 6311 - State Street @ Center Street | Y4: 6311 - State Street @ Center Street | AE4: 6311 - State Street @ Center Street
A5: May 5 2026 at 00:00:00 - May 6 2026 at 00:00:00 | G5: May 6 2026 at 00:00:00 - May 7 2026 at 00:00:00 | M5: May 18 2026 at 00:00:00 - May 19 2026 at 00:00:00 | S5: June 23 2026 at 00:00:00 - June 24 2026 at 00:00:00 | Y5: July 14 2026 at 00:00:00 - July 15 2026 at 00:00:00 | AE5: July 15 2026 at 00:00:00 - July 16 2026 at 00:00:00
A7: Approach Delay Summary | G7: Approach Delay Summary | M7: Approach Delay Summary | S7: Approach Delay Summary | Y7: Approach Delay Summary | AE7: Approach Delay Summary
A8: Average Approach Delay | B8: =AVERAGE(B16:B111,E16:E111) -> 19.642552 | C8: Sec/Veh | G8: Average Approach Delay | H8: =AVERAGE(H16:H111,K16:K111) -> 20.643594 | I8: Sec/Veh | M8: Average Approach Delay | N8: =AVERAGE(N16:N111,Q16:Q111) -> 19.399479 | O8: Sec/Veh | S8: Average Approach Delay | T8: =AVERAGE(T16:T111,W16:W111) -> 19.91125 | U8: Sec/Veh | Y8: Average Approach Delay | Z8: =AVERAGE(Z16:Z111,AC16:AC111) -> 19.664115 | AA8: Sec/Veh | AE8: Average Approach Delay | AF8: =AVERAGE(AF16:AF111,AI16:AI111) -> 20.194219 | AG8: Sec/Veh
A9: NBT Ph2 | B9: =AVERAGE(B16:B111) -> 16.134583 | C9: Sec/Veh | G9: NBT Ph2 | H9: =AVERAGE(H16:H111) -> 17.152708 | I9: Sec/Veh | M9: NBT Ph2 | N9: =AVERAGE(N16:N111) -> 16.449896 | O9: Sec/Veh | S9: NBT Ph2 | T9: =AVERAGE(T16:T111) -> 15.277292 | U9: Sec/Veh | Y9: NBT Ph2 | Z9: =AVERAGE(Z16:Z111) -> 14.661562 | AA9: Sec/Veh | AE9: NBT Ph2 | AF9: =AVERAGE(AF16:AF111) -> 15.768125 | AG9: Sec/Veh
A10: SBT Ph6 | B10: =AVERAGE(E16:E111) -> 23.150521 | C10: Sec/Veh | G10: SBT Ph6 | H10: =AVERAGE(K16:K111) -> 24.134479 | I10: Sec/Veh | M10: SBT Ph6 | N10: =AVERAGE(Q16:Q111) -> 22.349063 | O10: Sec/Veh | S10: SBT Ph6 | T10: =AVERAGE(W16:W111) -> 24.545208 | U10: Sec/Veh | Y10: SBT Ph6 | Z10: =AVERAGE(AC16:AC111) -> 24.666667 | AA10: Sec/Veh | AE10: SBT Ph6 | AF10: =AVERAGE(AI16:AI111) -> 24.620313 | AG10: Sec/Veh
A12: NBT Ph2 | D12: SBT Ph6 | G12: NBT Ph2 | J12: SBT Ph6 | M12: NBT Ph2 | P12: SBT Ph6 | S12: NBT Ph2 | V12: SBT Ph6 | Y12: NBT Ph2 | AB12: SBT Ph6 | AE12: NBT Ph2 | AH12: SBT Ph6
A13: Approach Delay | D13: Approach Delay | G13: Approach Delay | J13: Approach Delay | M13: Approach Delay | P13: Approach Delay | S13: Approach Delay | V13: Approach Delay | Y13: Approach Delay | AB13: Approach Delay | AE13: Approach Delay | AH13: Approach Delay
A14: Per Vehicle | D14: Per Vehicle | G14: Per Vehicle | J14: Per Vehicle | M14: Per Vehicle | P14: Per Vehicle | S14: Per Vehicle | V14: Per Vehicle | Y14: Per Vehicle | AB14: Per Vehicle | AE14: Per Vehicle | AH14: Per Vehicle
A15: (per second) | D15: (per second) | G15: (per second) | J15: (per second) | M15: (per second) | P15: (per second) | S15: (per second) | V15: (per second) | Y15: (per second) | AB15: (per second) | AE15: (per second) | AH15: (per second)
A16: 1777960800000 | B16: 4.83 | D16: 1777960800000 | E16: 8.45 | G16: 1778047200000 | H16: 5.13 | J16: 1778047200000 | K16: 8.09 | M16: 1779084000000 | N16: 2.54 | P16: 1779084000000 | Q16: 7.33 | S16: 1782194400000 | T16: 11.64 | V16: 1782194400000 | W16: 12.4 | Y16: 1784008800000 | Z16: 8.31 | AB16: 1784008800000 | AC16: 8.18 | AE16: 1784095200000 | AF16: 3.18 | AH16: 1784095200000 | AI16: 5.12
A17: 1777961700000 | B17: 4.66 | D17: 1777961700000 | E17: 6.21 | G17: 1778048100000 | H17: 1.95 | J17: 1778048100000 | K17: 4.92 | M17: 1779084900000 | N17: 2.43 | P17: 1779084900000 | Q17: 3.76 | S17: 1782195300000 | T17: 6.49 | V17: 1782195300000 | W17: 6.97 | Y17: 1784009700000 | Z17: 4.09 | AB17: 1784009700000 | AC17: 7.65 | AE17: 1784096100000 | AF17: 5.2 | AH17: 1784096100000 | AI17: 10.82
A18: 1777962600000 | B18: 0.92 | D18: 1777962600000 | E18: 4.55 | G18: 1778049000000 | H18: 4.34 | J18: 1778049000000 | K18: 6.9 | M18: 1779085800000 | N18: 1.92 | P18: 1779085800000 | Q18: 2.95 | S18: 1782196200000 | T18: 6.31 | V18: 1782196200000 | W18: 7.53 | Y18: 1784010600000 | Z18: 1.95 | AB18: 1784010600000 | AC18: 5.05 | AE18: 1784097000000 | AF18: 4.42 | AH18: 1784097000000 | AI18: 3.98
A19: 1777963500000 | B19: 2.47 | D19: 1777963500000 | E19: 3.54 | G19: 1778049900000 | H19: 2.88 | J19: 1778049900000 | K19: 4.17 | M19: 1779086700000 | N19: 2.15 | P19: 1779086700000 | Q19: 3.23 | S19: 1782197100000 | T19: 2.44 | V19: 1782197100000 | W19: 3.58 | Y19: 1784011500000 | Z19: 2.22 | AB19: 1784011500000 | AC19: 6.09 | AE19: 1784097900000 | AF19: 3.87 | AH19: 1784097900000 | AI19: 7.84
A20: 1777964400000 | B20: 1.78 | D20: 1777964400000 | E20: 3.65 | G20: 1778050800000 | H20: 3.73 | J20: 1778050800000 | K20: 5.34 | M20: 1779087600000 | N20: 1.57 | P20: 1779087600000 | Q20: 3.61 | S20: 1782198000000 | T20: 1.66 | V20: 1782198000000 | W20: 2.3 | Y20: 1784012400000 | Z20: 2.36 | AB20: 1784012400000 | AC20: 11.26 | AE20: 1784098800000 | AF20: 3.07 | AH20: 1784098800000 | AI20: 5.76
A21: 1777965300000 | B21: 2.19 | D21: 1777965300000 | E21: 2.65 | G21: 1778051700000 | H21: 1.49 | J21: 1778051700000 | K21: 2.72 | M21: 1779088500000 | N21: 1.29 | P21: 1779088500000 | Q21: 3.35 | S21: 1782198900000 | T21: 5.78 | V21: 1782198900000 | W21: 12.33 | Y21: 1784013300000 | Z21: 2.97 | AB21: 1784013300000 | AC21: 4.17 | AE21: 1784099700000 | AF21: 1.77 | AH21: 1784099700000 | AI21: 3.33
A22: 1777966200000 | B22: 1.64 | D22: 1777966200000 | E22: 3.18 | G22: 1778052600000 | H22: 1.51 | J22: 1778052600000 | K22: 2.4 | M22: 1779089400000 | N22: 3.51 | P22: 1779089400000 | Q22: 4.65 | S22: 1782199800000 | T22: 5.43 | V22: 1782199800000 | W22: 8.66 | Y22: 1784014200000 | Z22: 2.29 | AB22: 1784014200000 | AC22: 1.66 | AE22: 1784100600000 | AF22: 2.77 | AH22: 1784100600000 | AI22: 2.57
A23: 1777967100000 | B23: 0.83 | D23: 1777967100000 | E23: 1.02 | G23: 1778053500000 | H23: 2.66 | J23: 1778053500000 | K23: 3.24 | M23: 1779090300000 | N23: 1.75 | P23: 1779090300000 | Q23: 1.19 | S23: 1782200700000 | T23: 1.11 | V23: 1782200700000 | W23: 1.71 | Y23: 1784015100000 | Z23: 1.2 | AB23: 1784015100000 | AC23: 1.43 | AE23: 1784101500000 | AF23: 4.58 | AH23: 1784101500000 | AI23: 7.29
A24: 1777968000000 | B24: 2.78 | D24: 1777968000000 | E24: 2.83 | G24: 1778054400000 | H24: 1.44 | J24: 1778054400000 | K24: 1.51 | M24: 1779091200000 | N24: 1.23 | P24: 1779091200000 | Q24: 2.55 | S24: 1782201600000 | T24: 0.97 | V24: 1782201600000 | W24: 1.25 | Y24: 1784016000000 | Z24: 0.9 | AB24: 1784016000000 | AC24: 1.67 | AE24: 1784102400000 | AF24: 0.84 | AH24: 1784102400000 | AI24: 2.21
A25: 1777968900000 | B25: 1.14 | D25: 1777968900000 | E25: 1.65 | G25: 1778055300000 | H25: 0.39 | J25: 1778055300000 | K25: 0.98 | M25: 1779092100000 | N25: 1.43 | P25: 1779092100000 | Q25: 1.45 | S25: 1782202500000 | T25: 1.85 | V25: 1782202500000 | W25: 1.72 | Y25: 1784016900000 | Z25: 0.85 | AB25: 1784016900000 | AC25: 1.5 | AE25: 1784103300000 | AF25: 1.06 | AH25: 1784103300000 | AI25: 1.76
A26: 1777969800000 | B26: 1.13 | D26: 1777969800000 | E26: 0.92 | G26: 1778056200000 | H26: 1.44 | J26: 1778056200000 | K26: 1.99 | M26: 1779093000000 | N26: 1.01 | P26: 1779093000000 | Q26: 0.81 | S26: 1782203400000 | T26: 0.84 | V26: 1782203400000 | W26: 1.28 | Y26: 1784017800000 | Z26: 0.89 | AB26: 1784017800000 | AC26: 0.99 | AE26: 1784104200000 | AF26: 0.55 | AH26: 1784104200000 | AI26: 3.51
A27: 1777970700000 | B27: 0.88 | D27: 1777970700000 | E27: 0.89 | G27: 1778057100000 | H27: 1.33 | J27: 1778057100000 | K27: 1.54 | M27: 1779093900000 | N27: 1.36 | P27: 1779093900000 | Q27: 0.94 | S27: 1782204300000 | T27: 0.43 | V27: 1782204300000 | W27: 1.3 | Y27: 1784018700000 | Z27: 1.94 | AB27: 1784018700000 | AC27: 1.55 | AE27: 1784105100000 | AF27: 1.82 | AH27: 1784105100000 | AI27: 1
... A111: 1778046300000 | B111: 2.56 | D111: 1778046300000 | E111: 7.11 | G111: 1778132700000 | H111: 7.71 | J111: 1778132700000 | K111: 10.02 | M111: 1779169500000 | N111: 2.26 | P111: 1779169500000 | Q111: 3.77 | S111: 1782279900000 | T111: 7.18 | V111: 1782279900000 | W111: 9.94 | Y111: 1784094300000 | Z111: 9.39 | AB111: 1784094300000 | AC111: 9.73 | AE111: 1784180700000 | AF111: 6.08 | AH111: 1784180700000 | AI111: 8.23

Sheet Arrivals on Red
A1: Before Data Day 1 | G1: Before Data Day 2 | M1: Before Data Day 3 | S1: After Data Day 1 | Y1: After Data Day 2 | AE1: After Data Day 3
A2: Performance Measures - ATSPM | G2: Performance Measures - ATSPM | M2: Performance Measures - ATSPM | S2: Performance Measures - ATSPM | Y2: Performance Measures - ATSPM | AE2: Performance Measures - ATSPM
A3: Arrivals on Red | G3: Arrivals on Red | M3: Arrivals on Red | S3: Arrivals on Red | Y3: Arrivals on Red | AE3: Arrivals on Red
A4: 6311 - State Street @ Center Street | G4: 6311 - State Street @ Center Street | M4: 6311 - State Street @ Center Street | S4: 6311 - State Street @ Center Street | Y4: 6311 - State Street @ Center Street | AE4: 6311 - State Street @ Center Street
A5: May 5 2026 at 00:00:00 - May 6 2026 at 00:00:00 | G5: May 6 2026 at 00:00:00 - May 7 2026 at 00:00:00 | M5: May 18 2026 at 00:00:00 - May 19 2026 at 00:00:00 | S5: June 23 2026 at 00:00:00 - June 24 2026 at 00:00:00 | Y5: July 14 2026 at 00:00:00 - July 15 2026 at 00:00:00 | AE5: July 15 2026 at 00:00:00 - July 16 2026 at 00:00:00
A7: Arrivals on Red Summary | G7: Arrivals on Red Summary | M7: Arrivals on Red Summary | S7: Arrivals on Red Summary | Y7: Arrivals on Red Summary | AE7: Arrivals on Red Summary
A8: % Arrivals on Red | B8: =AVERAGE(B14:B109,E14:E109) -> 51.802031 | C8: % | G8: % Arrivals on Red | H8: =AVERAGE(H14:H109,K14:K109) -> 54.506979 | I8: % | M8: % Arrivals on Red | N8: =AVERAGE(N14:N109,Q14:Q109) -> 50.461927 | O8: % | S8: % Arrivals on Red | T8: =AVERAGE(T14:T109,W14:W109) -> 52.198125 | U8: % | Y8: % Arrivals on Red | Z8: =AVERAGE(Z14:Z109,AC14:AC109) -> 51.717604 | AA8: % | AE8: % Arrivals on Red | AF8: =AVERAGE(AF14:AF109,AI14:AI109) -> 52.046354 | AG8: %
A9: NBT Ph2 | B9: =AVERAGE(B14:B109) -> 46.609375 | C9: % | G9: NBT Ph2 | H9: =AVERAGE(H14:H109) -> 50.0325 | I9: % | M9: NBT Ph2 | N9: =AVERAGE(N14:N109) -> 46.075833 | O9: % | S9: NBT Ph2 | T9: =AVERAGE(T14:T109) -> 46.430312 | U9: % | Y9: NBT Ph2 | Z9: =AVERAGE(Z14:Z109) -> 45.02125 | AA9: % | AE9: NBT Ph2 | AF9: =AVERAGE(AF14:AF109) -> 45.876563 | AG9: %
A10: SBT Ph6 | B10: =AVERAGE(E14:E109) -> 56.994687 | C10: % | G10: SBT Ph6 | H10: =AVERAGE(K14:K109) -> 58.981458 | I10: % | M10: SBT Ph6 | N10: =AVERAGE(Q14:Q109) -> 54.848021 | O10: % | S10: SBT Ph6 | T10: =AVERAGE(W14:W109) -> 57.965938 | U10: % | Y10: SBT Ph6 | Z10: =AVERAGE(AC14:AC109) -> 58.413958 | AA10: % | AE10: SBT Ph6 | AF10: =AVERAGE(AI14:AI109) -> 58.216146 | AG10: %
A12: NBT Ph2 | D12: SBT Ph6 | G12: NBT Ph2 | J12: SBT Ph6 | M12: NBT Ph2 | P12: SBT Ph6 | S12: NBT Ph2 | V12: SBT Ph6 | Y12: NBT Ph2 | AB12: SBT Ph6 | AE12: NBT Ph2 | AH12: SBT Ph6
A13: % Arrivals on Red | D13: % Arrivals on Red | G13: % Arrivals on Red | J13: % Arrivals on Red | M13: % Arrivals on Red | P13: % Arrivals on Red | S13: % Arrivals on Red | V13: % Arrivals on Red | Y13: % Arrivals on Red | AB13: % Arrivals on Red | AE13: % Arrivals on Red | AH13: % Arrivals on Red
A14: 1777960800000 | B14: 44.12 | D14: 1777960800000 | E14: 46.26 | G14: 1778047200000 | H14: 40.91 | J14: 1778047200000 | K14: 51.83 | M14: 1779084000000 | N14: 26.48 | P14: 1779084000000 | Q14: 43.96 | S14: 1782194400000 | T14: 50.7 | V14: 1782194400000 | W14: 51.74 | Y14: 1784008800000 | Z14: 43.48 | AB14: 1784008800000 | AC14: 50.98 | AE14: 1784095200000 | AF14: 27.14 | AH14: 1784095200000 | AI14: 42.45
A15: 1777961700000 | B15: 43.4 | D15: 1777961700000 | E15: 44.83 | G15: 1778048100000 | H15: 20.74 | J15: 1778048100000 | K15: 42.12 | M15: 1779084900000 | N15: 29.78 | P15: 1779084900000 | Q15: 38.5 | S15: 1782195300000 | T15: 39.45 | V15: 1782195300000 | W15: 49.5 | Y15: 1784009700000 | Z15: 33.33 | AB15: 1784009700000 | AC15: 54.03 | AE15: 1784096100000 | AF15: 30.56 | AH15: 1784096100000 | AI15: 53.51
A16: 1777962600000 | B16: 11.27 | D16: 1777962600000 | E16: 33.85 | G16: 1778049000000 | H16: 39.44 | J16: 1778049000000 | K16: 50.43 | M16: 1779085800000 | N16: 25.88 | P16: 1779085800000 | Q16: 33.68 | S16: 1782196200000 | T16: 42.54 | V16: 1782196200000 | W16: 43.15 | Y16: 1784010600000 | Z16: 23.94 | AB16: 1784010600000 | AC16: 44.52 | AE16: 1784097000000 | AF16: 38.1 | AH16: 1784097000000 | AI16: 35.54
A17: 1777963500000 | B17: 26.83 | D17: 1777963500000 | E17: 31.94 | G17: 1778049900000 | H17: 26.64 | J17: 1778049900000 | K17: 37.01 | M17: 1779086700000 | N17: 25.27 | P17: 1779086700000 | Q17: 31.16 | S17: 1782197100000 | T17: 27.1 | V17: 1782197100000 | W17: 38.54 | Y17: 1784011500000 | Z17: 27.42 | AB17: 1784011500000 | AC17: 41.22 | AE17: 1784097900000 | AF17: 32.73 | AH17: 1784097900000 | AI17: 45.95
A18: 1777964400000 | B18: 23.94 | D18: 1777964400000 | E18: 34.67 | G18: 1778050800000 | H18: 35.19 | J18: 1778050800000 | K18: 37.93 | M18: 1779087600000 | N18: 18.94 | P18: 1779087600000 | Q18: 33.11 | S18: 1782198000000 | T18: 19.23 | V18: 1782198000000 | W18: 22.16 | Y18: 1784012400000 | Z18: 25 | AB18: 1784012400000 | AC18: 43.7 | AE18: 1784098800000 | AF18: 23.53 | AH18: 1784098800000 | AI18: 46.81
A19: 1777965300000 | B19: 24.52 | D19: 1777965300000 | E19: 27.86 | G19: 1778051700000 | H19: 22.75 | J19: 1778051700000 | K19: 28.79 | M19: 1779088500000 | N19: 12.36 | P19: 1779088500000 | Q19: 27.94 | S19: 1782198900000 | T19: 34.04 | V19: 1782198900000 | W19: 54.15 | Y19: 1784013300000 | Z19: 30.77 | AB19: 1784013300000 | AC19: 38.57 | AE19: 1784099700000 | AF19: 18.18 | AH19: 1784099700000 | AI19: 33.62
A20: 1777966200000 | B20: 15.83 | D20: 1777966200000 | E20: 23.96 | G20: 1778052600000 | H20: 17.03 | J20: 1778052600000 | K20: 22.65 | M20: 1779089400000 | N20: 28.34 | P20: 1779089400000 | Q20: 30.39 | S20: 1782199800000 | T20: 39.33 | V20: 1782199800000 | W20: 46.78 | Y20: 1784014200000 | Z20: 23.26 | AB20: 1784014200000 | AC20: 21.74 | AE20: 1784100600000 | AF20: 29.17 | AH20: 1784100600000 | AI20: 29.03
A21: 1777967100000 | B21: 11.04 | D21: 1777967100000 | E21: 13.42 | G21: 1778053500000 | H21: 29.06 | J21: 1778053500000 | K21: 28.95 | M21: 1779090300000 | N21: 18.11 | P21: 1779090300000 | Q21: 11.94 | S21: 1782200700000 | T21: 12.77 | V21: 1782200700000 | W21: 15.6 | Y21: 1784015100000 | Z21: 18.18 | AB21: 1784015100000 | AC21: 17.24 | AE21: 1784101500000 | AF21: 29.63 | AH21: 1784101500000 | AI21: 47.69
A22: 1777968000000 | B22: 22.73 | D22: 1777968000000 | E22: 29.53 | G22: 1778054400000 | H22: 12.9 | J22: 1778054400000 | K22: 15.84 | M22: 1779091200000 | N22: 12.61 | P22: 1779091200000 | Q22: 20.58 | S22: 1782201600000 | T22: 11.2 | V22: 1782201600000 | W22: 18.38 | Y22: 1784016000000 | Z22: 8 | AB22: 1784016000000 | AC22: 21.26 | AE22: 1784102400000 | AF22: 13.79 | AH22: 1784102400000 | AI22: 24.37
A23: 1777968900000 | B23: 17.39 | D23: 1777968900000 | E23: 17.6 | G23: 1778055300000 | H23: 6.96 | J23: 1778055300000 | K23: 12.62 | M23: 1779092100000 | N23: 8.58 | P23: 1779092100000 | Q23: 10.85 | S23: 1782202500000 | T23: 18.52 | V23: 1782202500000 | W23: 24 | Y23: 1784016900000 | Z23: 7.69 | AB23: 1784016900000 | AC23: 21.23 | AE23: 1784103300000 | AF23: 19.64 | AH23: 1784103300000 | AI23: 18.6
A24: 1777969800000 | B24: 10.46 | D24: 1777969800000 | E24: 13.03 | G24: 1778056200000 | H24: 12.89 | J24: 1778056200000 | K24: 15.28 | M24: 1779093000000 | N24: 12.93 | P24: 1779093000000 | Q24: 11.21 | S24: 1782203400000 | T24: 7.87 | V24: 1782203400000 | W24: 11.43 | Y24: 1784017800000 | Z24: 12.9 | AB24: 1784017800000 | AC24: 13.64 | AE24: 1784104200000 | AF24: 11.48 | AH24: 1784104200000 | AI24: 33.08
A25: 1777970700000 | B25: 10.31 | D25: 1777970700000 | E25: 14.78 | G25: 1778057100000 | H25: 15.98 | J25: 1778057100000 | K25: 16.78 | M25: 1779093900000 | N25: 17.35 | P25: 1779093900000 | Q25: 12.74 | S25: 1782204300000 | T25: 7.19 | V25: 1782204300000 | W25: 17.32 | Y25: 1784018700000 | Z25: 24.44 | AB25: 1784018700000 | AC25: 16.23 | AE25: 1784105100000 | AF25: 27.27 | AH25: 1784105100000 | AI25: 14.41
... A109: 1778046300000 | B109: 23.15 | D109: 1778046300000 | E109: 51.75 | G109: 1778132700000 | H109: 40.96 | J109: 1778132700000 | K109: 55.47 | M109: 1779169500000 | N109: 27.37 | P109: 1779169500000 | Q109: 36.63 | S109: 1782279900000 | T109: 47.37 | V109: 1782279900000 | W109: 57.04 | Y109: 1784094300000 | Z109: 44.34 | AB109: 1784094300000 | AC109: 57.49 | AE109: 1784180700000 | AF109: 46.55 | AH109: 1784180700000 | AI109: 53.51

Sheet Pedestrian Delay
A1: Before Data Day 1 | M1: Before Data Day 2 | Y1: Before Data Day 3 | AK1: After Data Day 1 | AW1: After Data Day 2 | BI1: After Data Day 3
A2: Performance Measures - ATSPM | C2: *Pedestrian delay records the delay each pedestrian encounters. This data is for each pedestrian, it is not sorted into bins. | M2: Performance Measures - ATSPM | O2: *Pedestrian delay records the delay each pedestrian encounters. This data is for each pedestrian, it is not sorted into bins. | Y2: Performance Measures - ATSPM | AA2: *Pedestrian delay records the delay each pedestrian encounters. This data is for each pedestrian, it is not sorted into bins. | AK2: Performance Measures - ATSPM | AM2: *Pedestrian delay records the delay each pedestrian encounters. This data is for each pedestrian, it is not sorted into bins. | AW2: Performance Measures - ATSPM | AY2: *Pedestrian delay records the delay each pedestrian encounters. This data is for each pedestrian, it is not sorted into bins. | BI2: Performance Measures - ATSPM | BK2: *Pedestrian delay records the delay each pedestrian encounters. This data is for each pedestrian, it is not sorted into bins.
A3: Pedestrian Delay | M3: Pedestrian Delay | Y3: Pedestrian Delay | AK3: Pedestrian Delay | AW3: Pedestrian Delay | BI3: Pedestrian Delay
A4: 6311 - State Street @ Center Street | M4: 6311 - State Street @ Center Street | Y4: 6311 - State Street @ Center Street | AK4: 6311 - State Street @ Center Street | AW4: 6311 - State Street @ Center Street | BI4: 6311 - State Street @ Center Street
A5: May 5 at 00.00 to May 6 at 00.00 | M5: May 6 at 00.00 to May 7 at 00.00 | Y5: May 18 at 00.00 to May 19 at 00.00 | AK5: June 23 at 00.00 to June 24 at 00.00 | AW5: July 14 at 00.00 to July 15 at 00.00 | BI5: July 15 at 00.00 to July 16 at 00.00
A7: Pedestrian Delay | M7: Pedestrian Delay | Y7: Pedestrian Delay | AK7: Pedestrian Delay | AW7: Pedestrian Delay | BI7: Pedestrian Delay
A8: Intersection Avg Delay | B8: =AVERAGE(B17:B82,E:E,H:H,K:K) -> 47.185824 | C8: Sec/Cycle | M8: Intersection Avg Delay | N8: =AVERAGE(N17:N90,Q:Q,T:T,W:W) -> 41.896644 | O8: Sec/Cycle | Y8: Intersection Avg Delay | Z8: =AVERAGE(Z17:Z84,AC:AC,AF:AF,AI:AI) -> 37.602247 | AA8: Sec/Cycle | AK8: Intersection Avg Delay | AL8: =AVERAGE(AL17:AL84,AO:AO,AR:AR,AU:AU) -> 37.320896 | AM8: Sec/Cycle | AW8: Intersection Avg Delay | AX8: =AVERAGE(AX17:AX84,BA:BA,BD:BD,BG:BG) -> 42.318981 | AY8: Sec/Cycle | BI8: Intersection Avg Delay | BJ8: =AVERAGE(BJ17:BJ89,BM:BM,BP:BP,BS:BS) -> 43.842324 | BK8: Sec/Cycle
A9: NBT Ph2 | B9: =AVERAGE(B17:B82) -> 40.113636 | C9: Sec/Cycle | M9: NBT Ph2 | N9: =AVERAGE(N17:N90) -> 41.583784 | O9: Sec/Cycle | Y9: NBT Ph2 | Z9: =AVERAGE(Z17:Z84) -> 28.826471 | AA9: Sec/Cycle | AK9: NBT Ph2 | AL9: =AVERAGE(AL17:AL84) -> 37.333333 | AM9: Sec/Cycle | AW9: NBT Ph2 | AX9: =AVERAGE(AX17:AX84) -> 44.420339 | AY9: Sec/Cycle | BI9: NBT Ph2 | BJ9: =AVERAGE(BJ17:BJ89) -> 42.578082 | BK9: Sec/Cycle
A10: EBT Ph4 | B10: =AVERAGE(E:E) -> 53.442424 | C10: Sec/Cycle | M10: EBT Ph4 | N10: =AVERAGE(Q:Q) -> 45.039759 | O10: Sec/Cycle | Y10: EBT Ph4 | Z10: =AVERAGE(AC:AC) -> 52.949275 | AA10: Sec/Cycle | AK10: EBT Ph4 | AL10: =AVERAGE(AO:AO) -> 43.455682 | AM10: Sec/Cycle | AW10: EBT Ph4 | AX10: =AVERAGE(BA:BA) -> 41.28 | AY10: Sec/Cycle | BI10: EBT Ph4 | BJ10: =AVERAGE(BM:BM) -> 55.367187 | BK10: Sec/Cycle
A11: SBT Ph6 | B11: =AVERAGE(H:H) -> 38.61875 | C11: Sec/Cycle | M11: SBT Ph6 | N11: =AVERAGE(T:T) -> 44.342857 | O11: Sec/Cycle | Y11: SBT Ph6 | Z11: =AVERAGE(AF:AF) -> 33.172222 | AA11: Sec/Cycle | AK11: SBT Ph6 | AL11: =AVERAGE(AR:AR) -> 31.411538 | AM11: Sec/Cycle | AW11: SBT Ph6 | AX11: =AVERAGE(BD:BD) -> 38.280851 | AY11: Sec/Cycle | BI11: SBT Ph6 | BJ11: =AVERAGE(BP:BP) -> 34.276563 | BK11: Sec/Cycle
A12: WBT Ph8 | B12: =AVERAGE(K:K) -> 52.92716 | C12: Sec/Cycle | M12: WBT Ph8 | N12: =AVERAGE(W:W) -> 36.873077 | O12: Sec/Cycle | Y12: WBT Ph8 | Z12: =AVERAGE(AI:AI) -> 35.132759 | AA12: Sec/Cycle | AK12: WBT Ph8 | AL12: =AVERAGE(AU:AU) -> 33.730769 | AM12: Sec/Cycle | AW12: WBT Ph8 | AX12: =AVERAGE(BG:BG) -> 44.554545 | AY12: Sec/Cycle | BI12: WBT Ph8 | BJ12: =AVERAGE(BS:BS) -> 43.015 | BK12: Sec/Cycle
A14: Direction | M14: Direction | Y14: Direction | AK14: Direction | AW14: Direction | BI14: Direction
A15: NBT Ph2 | D15: EBT Ph4 | G15: SBT Ph6 | J15: WBT Ph8 | M15: NBT Ph2 | P15: EBT Ph4 | S15: SBT Ph6 | V15: WBT Ph8 | Y15: NBT Ph2 | AB15: EBT Ph4 | AE15: SBT Ph6 | AH15: WBT Ph8 | AK15: NBT Ph2 | AN15: EBT Ph4 | AQ15: SBT Ph6 | AT15: WBT Ph8 | AW15: NBT Ph2 | AZ15: EBT Ph4 | BC15: SBT Ph6 | BF15: WBT Ph8 | BI15: NBT Ph2 | BL15: EBT Ph4 | BO15: SBT Ph6 | BR15: WBT Ph8
A16: Pedestrian Delay | D16: Pedestrian Delay | G16: Pedestrian Delay | J16: Pedestrian Delay | M16: Pedestrian Delay | P16: Pedestrian Delay | S16: Pedestrian Delay | V16: Pedestrian Delay | Y16: Pedestrian Delay | AB16: Pedestrian Delay | AE16: Pedestrian Delay | AH16: Pedestrian Delay | AK16: Pedestrian Delay | AN16: Pedestrian Delay | AQ16: Pedestrian Delay | AT16: Pedestrian Delay | AW16: Pedestrian Delay | AZ16: Pedestrian Delay | BC16: Pedestrian Delay | BF16: Pedestrian Delay | BI16: Pedestrian Delay | BL16: Pedestrian Delay | BO16: Pedestrian Delay | BR16: Pedestrian Delay
A17: 1777962217006 | B17: 0.3 | D17: 1777982049001 | E17: 80.1 | G17: 1777960816008 | H17: 0.3 | J17: 1777961065000 | K17: 0.3 | M17: 1778059282004 | N17: 81.7 | P17: 1778070138006 | Q17: 18.3 | S17: 1778066759001 | T17: 29.9 | V17: 1778058936009 | W17: 6.2 | Y17: 1779089736000 | Z17: 0.3 | AB17: 1779110146003 | AC17: 6.1 | AE17: 1779103475005 | AF17: 18.5 | AH17: 1779092497002 | AI17: 9.4 | AK17: 1782194782005 | AL17: 0.3 | AN17: 1782196859004 | AO17: 59.7 | AQ17: 1782198385005 | AR17: 0.3 | AT17: 1782195038002 | AU17: 35.9 | AW17: 1784022877006 | AX17: 0.3 | AZ17: 1784030429005 | BA17: 15 | BC17: 1784030375005 | BD17: 13.5 | BF17: 1784012496005 | BG17: 42 | BI17: 1784096859005 | BJ17: 0.3 | BL17: 1784118691000 | BM17: 82.7 | BO17: 1784095381006 | BP17: 0.3 | BR17: 1784098751009 | BS17: 14.9
A18: 1777983843002 | B18: 23.9 | D18: 1777982198001 | E18: 29.1 | G18: 1777961108004 | H18: 39.4 | J18: 1777974651001 | K18: 7.4 | M18: 1778059632006 | N18: 91.9 | P18: 1778070831008 | Q18: 59.2 | S18: 1778070908006 | T18: 35.3 | V18: 1778059206004 | W18: 0.3 | Y18: 1779089793006 | Z18: 0.3 | AB18: 1779110939002 | AC18: 64.9 | AE18: 1779106317007 | AF18: 8 | AH18: 1779101806005 | AI18: 18.5 | AK18: 1782195105005 | AL18: 0.3 | AN18: 1782201439006 | AO18: 6.2 | AQ18: 1782202065007 | AR18: 0.3 | AT18: 1782199540001 | AU18: 28 | AW18: 1784031691006 | AX18: 0.3 | AZ18: 1784030587009 | BA18: 46.3 | BC18: 1784031793008 | BD18: 0.3 | BF18: 1784013219005 | BG18: 13.7 | BI18: 1784096859008 | BJ18: 0 | BL18: 1784119089000 | BM18: 94.8 | BO18: 1784116856006 | BP18: 0.3 | BR18: 1784117945006 | BS18: 2
A19: 1777984081008 | B19: 29.8 | D19: 1777983953009 | E19: 0.3 | G19: 1777965709005 | H19: 0.3 | J19: 1777974715006 | K19: 10 | M19: 1778072994003 | N19: 28.7 | P19: 1778072423002 | Q19: 32.4 | S19: 1778072736001 | T19: 32.6 | V19: 1778059321002 | W19: 23.9 | Y19: 1779089842005 | Z19: 0.3 | AB19: 1779111732005 | AC19: 71.1 | AE19: 1779106440008 | AF19: 108.7 | AH19: 1779107626000 | AI19: 0.2 | AK19: 1782195847006 | AL19: 0.3 | AN19: 1782214329006 | AO19: 8.3 | AQ19: 1782214373001 | AR19: 0.3 | AT19: 1782206212009 | AU19: 6.2 | AW19: 1784032102004 | AX19: 0.3 | AZ19: 1784031228006 | BA19: 31.6 | BC19: 1784032626002 | BD19: 17.3 | BF19: 1784026426008 | BG19: 6.3 | BI19: 1784115398003 | BJ19: 15.3 | BL19: 1784119617000 | BM19: 57.9 | BO19: 1784117741004 | BP19: 54.3 | BR19: 1784123313000 | BS19: 59.3
A20: 1777986988001 | B20: 1.8 | D20: 1777984425000 | E20: 15.4 | G20: 1777982090006 | H20: 20.5 | J20: 1777975194003 | K20: 27.6 | M20: 1778075904000 | N20: 50.1 | P20: 1778073084009 | Q20: 79.2 | S20: 1778072869002 | T20: 8.2 | V20: 1778059705009 | W20: 6.7 | Y20: 1779090147005 | Z20: 0.3 | AB20: 1779112126009 | AC20: 40.5 | AE20: 1779106839009 | AF20: 6.1 | AH20: 1779107757000 | AI20: 34.3 | AK20: 1782195847009 | AL20: 0 | AN20: 1782215668003 | AO20: 0.3 | AQ20: 1782216497004 | AR20: 24.3 | AT20: 1782212146001 | AU20: 34.5 | AW20: 1784032724000 | AX20: 66.8 | AZ20: 1784031739008 | BA20: 3.3 | BC20: 1784033293005 | BD20: 38.7 | BF20: 1784032153006 | BG20: 35 | BI20: 1784120455002 | BJ20: 6.1 | BL20: 1784123329008 | BM20: 37.8 | BO20: 1784119156001 | BP20: 24.1 | BR20: 1784125161000 | BS20: 95
A21: 1777987904001 | B21: 27.9 | D21: 1777986405000 | E21: 0 | G21: 1777984507005 | H21: 41.7 | J21: 1777975895003 | K21: 6.2 | M21: 1778077224000 | N21: 30.6 | P21: 1778073857006 | Q21: 40.5 | S21: 1778073532005 | T21: 41.6 | V21: 1778059844004 | W21: 0 | Y21: 1779090362005 | Z21: 0.3 | AB21: 1779112652002 | AC21: 71.2 | AE21: 1779112070001 | AF21: 0 | AH21: 1779109209000 | AI21: 7.3 | AK21: 1782196807006 | AL21: 13.1 | AN21: 1782216455009 | AO21: 40.2 | AQ21: 1782216653000 | AR21: 0.3 | AT21: 1782212226006 | AU21: 11.8 | AW21: 1784037768000 | AX21: 28.9 | AZ21: 1784032568002 | BA21: 54.7 | BC21: 1784039377000 | BD21: 71.4 | BF21: 1784033349000 | BG21: 22.1 | BI21: 1784122716000 | BJ21: 56.2 | BL21: 1784123593000 | BM21: 108.3 | BO21: 1784119693001 | BP21: 24 | BR21: 1784125425000 | BS21: 2.9
A22: 1777989487001 | B22: 20.6 | D22: 1777986947000 | E22: 0.2 | G22: 1777986353000 | H22: 0 | J22: 1777976046003 | K22: 46.4 | M22: 1778078416001 | N22: 0 | P22: 1778074539000 | Q22: 14.8 | S22: 1778074741000 | T22: 55.4 | V22: 1778059909003 | W22: 0 | Y22: 1779090549001 | Z22: 8.7 | AB22: 1779114885000 | AC22: 33.6 | AE22: 1779114710006 | AF22: 0 | AH22: 1779110265000 | AI22: 42.7 | AK22: 1782199492007 | AL22: 0.3 | AN22: 1782217152002 | AO22: 25.3 | AQ22: 1782217100007 | AR22: 0.3 | AT22: 1782216711009 | AU22: 62.7 | AW22: 1784038028003 | AX22: 53.5 | AZ22: 1784033232000 | BA22: 5.2 | BC22: 1784039507008 | BD22: 22.1 | BF22: 1784033349002 | BG22: 0 | BI22: 1784123217002 | BJ22: 66.1 | BL22: 1784123988002 | BM22: 27.3 | BO22: 1784120752008 | BP22: 69.1 | BR22: 1784128725000 | BS22: 51.6
A23: 1777992408000 | B23: 19.2 | D23: 1777989428002 | E23: 49.1 | G23: 1777987007003 | H23: 61.1 | J23: 1777978535002 | K23: 16.2 | M23: 1778078540007 | N23: 111.9 | P23: 1778077161000 | Q23: 8.1 | S23: 1778074873000 | T23: 25.7 | V23: 1778060754003 | W23: 6.7 | Y23: 1779090702008 | Z23: 0.3 | AB23: 1779116883000 | AC23: 20.7 | AE23: 1779114832001 | AF23: 21.6 | AH23: 1779111585000 | AI23: 10.3 | AK23: 1782199492009 | AL23: 0 | AN23: 1782217352005 | AO23: 50.3 | AQ23: 1782217974005 | AR23: 20.6 | AT23: 1782217165007 | AU23: 30 | AW23: 1784038417003 | AX23: 25.9 | AZ23: 1784037056006 | BA23: 26.1 | BC23: 1784040417004 | BD23: 36.9 | BF23: 1784035329000 | BG23: 35.4 | BI23: 1784124151003 | BJ23: 7 | BL23: 1784124384008 | BM23: 0.2 | BO23: 1784121561005 | BP23: 0 | BR23: 1784128989000 | BS23: 30.4
A24: 1777992804000 | B24: 113.3 | D24: 1777990115000 | E24: 5.9 | G24: 1777987927004 | H24: 68.7 | J24: 1777982198001 | K24: 9.8 | M24: 1778080260000 | N24: 45.9 | P24: 1778078492002 | Q24: 70.9 | S24: 1778075137000 | T24: 64.8 | V24: 1778061248005 | W24: 7.9 | Y24: 1779090849008 | Z24: 19.4 | AB24: 1779118723009 | AC24: 51.5 | AE24: 1779117339003 | AF24: 10.1 | AH24: 1779112641000 | AI24: 114.7 | AK24: 1782215725007 | AL24: 62.7 | AN24: 1782217914000 | AO24: 29.8 | AQ24: 1782219813007 | AR24: 16 | AT24: 1782218025000 | AU24: 8.9 | AW24: 1784038690008 | AX24: 15.4 | AZ24: 1784038510001 | BA24: 64.7 | BC24: 1784045046001 | BD24: 34.7 | BF24: 1784036253000 | BG24: 48.9 | BI24: 1784124556008 | BJ24: 29.2 | BL24: 1784124512005 | BM24: 94.5 | BO24: 1784121675003 | BP24: 21.7 | BR24: 1784132022000 | BS24: 76.9
A25: 1777993985005 | B25: 66.8 | D25: 1777992488002 | E25: 95.8 | G25: 1777988734000 | H25: 61 | J25: 1777984425000 | K25: 23.6 | M25: 1778081572005 | N25: 13.6 | P25: 1778079159000 | Q25: 53.1 | S25: 1778075268009 | T25: 55.9 | V25: 1778061413002 | W25: 80.3 | Y25: 1779091228000 | Z25: 0.3 | AB25: 1779120972000 | AC25: 83.1 | AE25: 1779121570001 | AF25: 34.1 | AH25: 1779112773000 | AI25: 27.9 | AK25: 1782218331001 | AL25: 6.5 | AN25: 1782218435000 | AO25: 105.6 | AQ25: 1782220880002 | AR25: 47.5 | AT25: 1782219345000 | AU25: 14.8 | AW25: 1784042517001 | AX25: 39.8 | AZ25: 1784040495000 | BA25: 25 | BC25: 1784045184000 | BD25: 51.4 | BF25: 1784037045000 | BG25: 26.6 | BI25: 1784125351008 | BJ25: 22.5 | BL25: 1784124909007 | BM25: 5.3 | BO25: 1784122986006 | BP25: 13.3 | BR25: 1784134926000 | BS25: 2.8
A26: 1778000456000 | B26: 65.4 | D26: 1777993153000 | E26: 123.8 | G26: 1777991113000 | H26: 32.1 | J26: 1777987065000 | K26: 46 | M26: 1778082217002 | N26: 4.8 | P26: 1778081529009 | Q26: 9.1 | S26: 1778077513000 | T26: 14.1 | V26: 1778061488006 | W26: 6.2 | Y26: 1779092403000 | Z26: 0.3 | AB26: 1779121104000 | AC26: 25.3 | AE26: 1779122086002 | AF26: 39.4 | AH26: 1779120294000 | AI26: 2.9 | AK26: 1782218858006 | AL26: 21.7 | AN26: 1782221470009 | AO26: 20.2 | AQ26: 1782222197009 | AR26: 35 | AT26: 1782219477000 | AU26: 13.9 | AW26: 1784043439006 | AX26: 47.9 | AZ26: 1784042340006 | BA26: 78.1 | BC26: 1784045313006 | BD26: 51.2 | BF26: 1784037705000 | BG26: 13.7 | BI26: 1784125737003 | BJ26: 62.3 | BL26: 1784125293000 | BM26: 27.4 | BO26: 1784123921006 | BP26: 36.6 | BR26: 1784135454000 | BS26: 49.5
A27: 1778000845002 | B27: 7.1 | D27: 1777998428006 | E27: 14.7 | G27: 1777993489000 | H27: 77.3 | J27: 1777987329000 | K27: 60.5 | M27: 1778082368000 | N27: 29.2 | P27: 1778082438000 | Q27: 48.3 | S27: 1778081070006 | T27: 70.2 | V27: 1778061567000 | W27: 67 | Y27: 1779092879001 | Z27: 15.2 | AB27: 1779121632000 | AC27: 49.6 | AE27: 1779122205006 | AF27: 15.2 | AH27: 1779121482000 | AI27: 2.6 | AK27: 1782220858002 | AL27: 39 | AN27: 1782221869001 | AO27: 71.6 | AQ27: 1782223118000 | AR27: 17.4 | AT27: 1782220401000 | AU27: 33.5 | AW27: 1784045948000 | AX27: 41.9 | AZ27: 1784043260003 | BA27: 0.2 | BC27: 1784048081001 | BD27: 77.6 | BF27: 1784037837000 | BG27: 61 | BI27: 1784126135000 | BJ27: 199.4 | BL27: 1784127285007 | BM27: 36.2 | BO27: 1784124450007 | BP27: 17.9 | BR27: 1784136246000 | BS27: 32
A28: 1778002430004 | B28: 6 | D28: 1778000148009 | E28: 0.2 | G28: 1777994017000 | H28: 1.9 | J28: 1777987989000 | K28: 51.8 | M28: 1778082896000 | N28: 68.2 | P28: 1778082716007 | Q28: 110.7 | S28: 1778083309000 | T28: 26.6 | V28: 1778061632002 | W28: 0.3 | Y28: 1779106317007 | Z28: 8 | AB28: 1779122406000 | AC28: 9.2 | AE28: 1779122478005 | AF28: 26 | AH28: 1779121746000 | AI28: 23.2 | AK28: 1782224017007 | AL28: 66.5 | AN28: 1782222399000 | AO28: 90.9 | AQ28: 1782224833009 | AR28: 60.8 | AT28: 1782222117000 | AU28: 31.9 | AW28: 1784046740000 | AX28: 18.9 | AZ28: 1784044319002 | BA28: 24.4 | BC28: 1784048462002 | BD28: 13.5 | BF28: 1784038497000 | BG28: 112.3 | BI28: 1784127859005 | BJ28: 82 | BL28: 1784129927006 | BM28: 1.2 | BO28: 1784125513000 | BP28: 72.3 | BR28: 1784137698000 | BS28: 6.5
... A56: 1778021281002 | B56: 55.6 | D56: 1778018211006 | E56: 53.6 | G56: 1778030314009 | H56: 38.1 | J56: 1778004090000 | K56: 17.9 | M56: 1778104391000 | N56: 20 | P56: 1778102813003 | Q56: 9 | S56: 1778109755006 | T56: 2.1 | V56: 1778088906000 | W56: 61.8 | Y56: 1779136856000 | Z56: 4.4 | AB56: 1779141112002 | AC56: 61.4 | AE56: 1779142355005 | AF56: 55.2 | AH56: 1779147694000 | AI56: 46.9 | AK56: 1782257287003 | AL56: 52.7 | AN56: 1782243648000 | AO56: 121.1 | AQ56: 1782257114007 | AR56: 0 | AT56: 1782252844000 | AU56: 40.4 | AW56: 1784071541000 | AX56: 26.1 | AZ56: 1784068157002 | BA56: 27.4 | BC56: 1784077779008 | BD56: 20.3 | BF56: 1784073245006 | BG56: 0.2 | BI56: 1784148048005 | BJ56: 71.8 | BL56: 1784153205002 | BM56: 132.8 | BO56: 1784152661000 | BP56: 49.7 | BR56: 1784177237009 | BS56: 36.2
A57: 1778023239002 | B57: 32.2 | D57: 1778018366000 | E57: 141.5 | G57: 1778032282004 | H57: 30.1 | J57: 1778006730000 | K57: 54.7 | M57: 1778104977008 | N57: 46.1 | P57: 1778104007005 | Q57: 30.1 | S57: 1778109911000 | T57: 74.4 | V57: 1778089302000 | W57: 36.4 | Y57: 1779139231006 | Z57: 51.7 | AB57: 1779141863008 | AC57: 113.1 | AE57: 1779143709009 | AF57: 15.1 | AH57: 1779147994000 | AI57: 138.4 | AK57: 1782258038002 | AL57: 23.9 | AN57: 1782243912000 | AO57: 63.1 | AQ57: 1782258914006 | AR57: 0 | AT57: 1782253444000 | AU57: 117.1 | AW57: 1784071990004 | AX57: 2.5 | AZ57: 1784068316000 | BA57: 48.3 | BC57: 1784078693006 | BD57: 38.4 | BF57: 1784073245008 | BG57: 0 | BI57: 1784148568000 | BJ57: 66.9 | BL57: 1784153512003 | BM57: 133 | BO57: 1784154461000 | BP57: 62.1
A58: 1778023832003 | B58: 79.4 | D58: 1778019265004 | E58: 0 | G58: 1778033088000 | H58: 63.4 | J58: 1778007258000 | K58: 20.7 | M58: 1778105284003 | N58: 35.1 | P58: 1778104165008 | Q58: 36.6 | S58: 1778110511000 | T58: 64.9 | V58: 1778090754000 | W58: 3.8 | Y58: 1779141031000 | Z58: 23.4 | AB58: 1779142309001 | AC58: 25.2 | AE58: 1779144161000 | AF58: 52.3 | AH58: 1779148144000 | AI58: 67.5 | AK58: 1782259234002 | AL58: 46.9 | AN58: 1782244836000 | AO58: 50.8 | AQ58: 1782259055004 | AR58: 24.2 | AT58: 1782254044000 | AU58: 34.3 | AW58: 1784072891000 | AX58: 78.9 | AZ58: 1784069959001 | BA58: 13.6 | BC58: 1784083068000 | BD58: 53.5 | BF58: 1784074144000 | BG58: 123.1 | BI58: 1784149521002 | BJ58: 36.5 | BL58: 1784153655002 | BM58: 63.5 | BO58: 1784155661000 | BP58: 24.3
A59: 1778024591000 | B59: 50.5 | D59: 1778019415002 | E59: 99.1 | G59: 1778036255001 | H59: 57.3 | J59: 1778007918000 | K59: 13.8 | M59: 1778106482007 | N59: 0 | P59: 1778105206003 | Q59: 70.5 | S59: 1778110661000 | T59: 95 | V59: 1778091414001 | W59: 0 | Y59: 1779141341000 | Z59: 76.9 | AB59: 1779142466000 | AC59: 19.9 | AE59: 1779144808009 | AF59: 18.8 | AH59: 1779148594000 | AI59: 14.9 | AK59: 1782259689005 | AL59: 54 | AN59: 1782244962009 | AO59: 35.5 | AQ59: 1782262209007 | AR59: 0.5 | AT59: 1782254498008 | AU59: 0.2 | AW59: 1784074985009 | AX59: 9.1 | AZ59: 1784070416000 | BA59: 70.1 | BC59: 1784083322009 | BD59: 68.8 | BF59: 1784074599002 | BG59: 0.2 | BI59: 1784149981001 | BJ59: 8.2 | BL59: 1784155756006 | BM59: 14 | BO59: 1784156259009 | BP59: 71.3
A60: 1778025337007 | B60: 63.8 | D60: 1778020311000 | E60: 20.7 | G60: 1778036645004 | H60: 112.5 | J60: 1778009502000 | K60: 5 | M60: 1778106632006 | N60: 119.4 | P60: 1778105659007 | Q60: 73.2 | S60: 1778111861000 | T60: 90.5 | V60: 1778092602000 | W60: 54.2 | Y60: 1779141488000 | Z60: 0 | AB60: 1779143213001 | AC60: 53.4 | AE60: 1779145062005 | AF60: 44.5 | AH60: 1779148744000 | AI60: 110.6 | AK60: 1782259838005 | AL60: 1.4 | AN60: 1782245100001 | AO60: 0 | AQ60: 1782264439000 | AR60: 53.4 | AT60: 1782256444000 | AU60: 9.1 | AW60: 1784075885000 | AX60: 5.5 | AZ60: 1784070858009 | BA60: 38.5 | BC60: 1784083464000 | BD60: 21.8 | BF60: 1784075494000 | BG60: 116.7 | BI60: 1784150738006 | BJ60: 46.9 | BL60: 1784157407007 | BM60: 80 | BO60: 1784156560006 | BP60: 21.8
A61: 1778025788007 | B61: 43.6 | D61: 1778020910009 | E61: 4.6 | G61: 1778038230005 | H61: 28.2 | J61: 1778010294000 | K61: 21 | M61: 1778106924009 | N61: 50.2 | P61: 1778105966000 | Q61: 24.5 | S61: 1778115011000 | T61: 11.3 | V61: 1778093922001 | W61: 0 | Y61: 1779142682005 | Z61: 57.2 | AB61: 1779145021003 | AC61: 75.4 | AE61: 1779145511000 | AF61: 86.8 | AH61: 1779149194009 | AI61: 0.2 | AK61: 1782261031008 | AL61: 40.2 | AN61: 1782246683006 | AO61: 21.7 | AQ61: 1782265104000 | AR61: 64 | AT61: 1782257344000 | AU61: 89.7 | AW61: 1784076477004 | AX61: 59 | AZ61: 1784074156000 | BA61: 61.7 | BC61: 1784086867006 | BD61: 41.3 | BF61: 1784075794000 | BG61: 25.8 | BI61: 1784152377005 | BJ61: 72.8 | BL61: 1784157559003 | BM61: 35.7 | BO61: 1784158964004 | BP61: 0
A62: 1778026230008 | B62: 54.4 | D62: 1778021066000 | E62: 72.4 | G62: 1778039791001 | H62: 66.4 | J62: 1778010690000 | K62: 84 | M62: 1778107688007 | N62: 53.3 | P62: 1778106116000 | Q62: 111.9 | S62: 1778115461000 | T62: 76.2 | V62: 1778095638000 | W62: 22.4 | Y62: 1779143579007 | Z62: 36.9 | AB62: 1779145460008 | AC62: 49.3 | AE62: 1779145661000 | AF62: 42.5 | AH62: 1779149496002 | AI62: 0.2 | AK62: 1782261332008 | AL62: 50.3 | AN62: 1782247080004 | AO62: 0.2 | AQ62: 1782265620006 | AR62: 16.2 | AT62: 1782258244000 | AU62: 2.2 | AW62: 1784077361000 | AX62: 67.9 | AZ62: 1784074460000 | BA62: 0 | BC62: 1784087004006 | BD62: 14.5 | BF62: 1784076994000 | BG62: 128.9 | BI62: 1784152522007 | BJ62: 31.6 | BL62: 1784157711003 | BM62: 3.2 | BO62: 1784159410005 | BP62: 76.3
A63: 1778027429004 | B63: 92 | D63: 1778021364004 | E63: 133.7 | G63: 1778044241007 | H63: 57.3 | J63: 1778011218000 | K63: 1.7 | M63: 1778107987002 | N63: 123.9 | P63: 1778106563007 | Q63: 75.6 | S63: 1778115792000 | T63: 56.7 | V63: 1778096562000 | W63: 79.7 | Y63: 1779144188006 | Z63: 16.2 | AB63: 1779145915002 | AC63: 118.5 | AE63: 1779146411000 | AF63: 87.2 | AH63: 1779150694000 | AI63: 0.5 | AK63: 1782262382002 | AL63: 234 | AN63: 1782247476000 | AO63: 49.2 | AQ63: 1782266552005 | AR63: 85.4 | AT63: 1782258994000 | AU63: 84.4 | AW63: 1784078935000 | AX63: 46.5 | AZ63: 1784074757005 | BA63: 122.1 | BC63: 1784091454004 | BD63: 34 | BF63: 1784077146008 | BG63: 0.2 | BI63: 1784152680009 | BJ63: 1.4 | BL63: 1784158305002 | BM63: 43.1 | BO63: 1784160011000 | BP63: 6.1
A64: 1778027607005 | B64: 0 | D64: 1778021516000 | E64: 96.4 | G64: 1778045259001 | H64: 0 | J64: 1778012538000 | K64: 67.8 | M64: 1778108738005 | N64: 11 | P64: 1778106710007 | Q64: 43.9 | S64: 1778116188000 | T64: 9.9 | V64: 1778100522000 | W64: 66.7 | Y64: 1779147191000 | Z64: 26.2 | AB64: 1779146066000 | AC64: 60.1 | AE64: 1779147011000 | AF64: 64.7 | AH64: 1779151444000 | AI64: 56.2 | AK64: 1782263885005 | AL64: 41.9 | AN64: 1782248992006 | AO64: 27.5 | AQ64: 1782271835004 | AR64: 2.1 | AT64: 1782259144001 | AU64: 0 | AW64: 1784079076004 | AX64: 59.8 | AZ64: 1784077307008 | BA64: 0.2 | BF64: 1784077566000 | BG64: 40 | BI64: 1784154941000 | BJ64: 60.7 | BL64: 1784159239008 | BM64: 51 | BO64: 1784160149002 | BP64: 36.1
A65: 1778027717001 | B65: 103.9 | D65: 1778021816000 | E65: 43.7 | J65: 1778012802000 | K65: 95.4 | M65: 1778109786000 | N65: 55.5 | P65: 1778107616000 | Q65: 8.2 | S65: 1778116848000 | T65: 34.7 | V65: 1778100786000 | W65: 102.7 | Y65: 1779147338008 | Z65: 50.7 | AB65: 1779147411009 | AC65: 41.9 | AE65: 1779147161000 | AF65: 33.7 | AH65: 1779152045005 | AI65: 0.2 | AK65: 1782264278000 | AL65: 10.5 | AN65: 1782249714008 | AO65: 76.5 | AQ65: 1782272748009 | AR65: 14.8 | AT65: 1782261394000 | AU65: 121.2 | AW65: 1784079476000 | AX65: 86.8 | AZ65: 1784077583000 | BA65: 97.5 | BF65: 1784078226000 | BG65: 26.9 | BI65: 1784156587003 | BJ65: 114.8 | BL65: 1784159966000 | BM65: 10.2 | BO65: 1784160761001 | BP65: 0
A66: 1778027884009 | B66: 51.7 | D66: 1778023760001 | E66: 0.2 | J66: 1778012934000 | K66: 102 | M66: 1778110391000 | N66: 36.1 | P66: 1778108366000 | Q66: 52.2 | S66: 1778118032006 | T66: 0.3 | V66: 1778102194000 | W66: 111.9 | Y66: 1779147788009 | Z66: 49 | AB66: 1779147865004 | AC66: 16 | AE66: 1779147611000 | AF66: 35.5 | AH66: 1779154482003 | AI66: 0 | AK66: 1782264545000 | AL66: 14.9 | AN66: 1782249866000 | AO66: 9 | AQ66: 1782273125002 | AR66: 17 | AT66: 1782262297001 | AU66: 0.2 | AW66: 1784079872000 | AX66: 111.3 | AZ66: 1784081262000 | BA66: 59.2 | BF66: 1784079810000 | BG66: 100.3 | BI66: 1784157191000 | BJ66: 53.1 | BL66: 1784160257004 | BM66: 12 | BO66: 1784161061000 | BP66: 54
A67: 1778028485003 | B67: 41 | D67: 1778025712001 | E67: 13.1 | J67: 1778013066000 | K67: 24.5 | M67: 1778110689000 | N67: 10.1 | P67: 1778109859006 | Q67: 126.6 | S67: 1778119355005 | T67: 63.3 | V67: 1778104144000 | W67: 89.1 | Y67: 1779150790000 | Z67: 91.7 | AB67: 1779150256008 | AC67: 119.9 | AE67: 1779151360003 | AF67: 3.4 | AH67: 1779154746000 | AI67: 0 | AK67: 1782265335000 | AL67: 0 | AN67: 1782250014003 | AO67: 32.3 | AQ67: 1782274173008 | AR67: 16.3 | AT67: 1782262444000 | AU67: 48.2 | AW67: 1784081852000 | AX67: 25.8 | AZ67: 1784082468000 | BA67: 72.8 | BF67: 1784081790000 | BG67: 124.4 | BI67: 1784157484003 | BJ67: 121.2 | BL67: 1784161312001 | BM67: 117.1 | BO67: 1784161211000 | BP67: 23.5
